Workbook

Sheet Course Data
A1: Last Name | B1: First Name | C1: Email | D1: Student ID | E1: Status | F1: Ligne de 'Passed' | G1: Hours in Course | H1: Overall Grade (Percentage) | I1: Chapter 1: What is Generative AI? | J1: Assignment : What does the model know about you? | K1: Chapter 2: Prompting strategies | L1: Quiz: Understanding Prompt Engineering | M1: Chapter 3: What are the main use cases and risks | N1: Assignment: Preparing personal use case prompts | O1: Chapter 4: Advanced Prompting strategies | P1: Chapter 5: Using Generative AI in my studies
A2: - | B2: Atishay | C2: atishay._@edu.escp.eu | D2: e243498 | E2: =IF(AND(G2>=5, H2>=50), "Passed", "Failed") -> Failed | F2: =IF(E2="Passed",ROW(), "") | G2: 0.81 | H2: 49.34 | I2: Complete | J2: Needs Grading | K2: Complete | L2: Complete | N2: Needs Grading
A3: - | B3: Harjot Singh | C3: harjot_singh._@edu.escp.eu | D3: e246602 | E3: =IF(AND(G3>=5, H3>=50), "Passed", "Failed") -> Failed | F3: =IF(E3="Passed",ROW(), "") | G3: 0.55 | H3: 0
A4: - | B4: Mohd Hamza | C4: mohd_hamza._@edu.escp.eu | D4: e225395 | E4: =IF(AND(G4>=5, H4>=50), "Passed", "Failed") -> Failed | F4: =IF(E4="Passed",ROW(), "") | G4: 0 | H4: 0
A5: - | B5: Purnima | C5: purnima._@edu.escp.eu | D5: e246598 | E5: =IF(AND(G5>=5, H5>=50), "Passed", "Failed") -> Failed | F5: =IF(E5="Passed",ROW(), "") | G5: 0.08 | H5: 0 | J5: Needs Grading
A6: - | B6: Sambhav | C6: sambhav._@edu.escp.eu | D6: e246599 | E6: =IF(AND(G6>=5, H6>=50), "Passed", "Failed") -> Failed | F6: =IF(E6="Passed",ROW(), "") | G6: 0.03 | H6: 0
A7: - | B7: Sohan Manjunatha | C7: sohan_manjunatha._@edu.escp.eu | D7: e220428 | E7: =IF(AND(G7>=5, H7>=50), "Passed", "Failed") -> Failed | F7: =IF(E7="Passed",ROW(), "") | G7: 0 | H7: 0
A8: - | B8: Suryanarayanan | C8: suryanarayanan._@edu.escp.eu | D8: e246600 | E8: =IF(AND(G8>=5, H8>=50), "Passed", "Failed") -> Failed | F8: =IF(E8="Passed",ROW(), "") | G8: 0 | H8: 0
A9: - | B9: Vedant Manu | C9: vedant_manu._@edu.escp.eu | D9: e246601 | E9: =IF(AND(G9>=5, H9>=50), "Passed", "Failed") -> Failed | F9: =IF(E9="Passed",ROW(), "") | G9: 0 | H9: 0
A10: . | B10: Aryan Raj | C10: aryan_raj._@edu.escp.eu | D10: e246605 | E10: =IF(AND(G10>=5, H10>=50), "Passed", "Failed") -> Failed | F10: =IF(E10="Passed",ROW(), "") | G10: 0 | H10: 0
A11: . | B11: Bhuvnesh | C11: bhuvnesh._@edu.escp.eu | D11: e246690 | E11: =IF(AND(G11>=5, H11>=50), "Passed", "Failed") -> Failed | F11: =IF(E11="Passed",ROW(), "") | G11: 0 | H11: 0
A12: . | B12: Gurkirat Singh | C12: gurkirat_singh._@edu.escp.eu | D12: e246604 | E12: =IF(AND(G12>=5, H12>=50), "Passed", "Failed") -> Failed | F12: =IF(E12="Passed",ROW(), "") | G12: 0 | H12: 0
A13: AAOUAJ | B13: Fatimaazzahra | C13: fatimaazzahra.aaouaj@edu.escp.eu | D13: e242650 | E13: =IF(AND(G13>=5, H13>=50), "Passed", "Failed") -> Failed | F13: =IF(E13="Passed",ROW(), "") | G13: 0 | H13: 0
A14: AARTS | B14: Max | C14: max.aarts@edu.escp.eu | D14: e231558 | E14: =IF(AND(G14>=5, H14>=50), "Passed", "Failed") -> Failed | F14: =IF(E14="Passed",ROW(), "") | G14: 0 | H14: 0
A15: ABAIBOU | B15: Elias | C15: elias.abaibou@edu.escp.eu | D15: e213195 | E15: =IF(AND(G15>=5, H15>=50), "Passed", "Failed") -> Failed | F15: =IF(E15="Passed",ROW(), "") | G15: 0 | H15: 0
A16: ABANDE | B16: Rutuja | C16: rutuja.abande@edu.escp.eu | D16: e243624 | E16: =IF(AND(G16>=5, H16>=50), "Passed", "Failed") -> Failed | F16: =IF(E16="Passed",ROW(), "") | G16: 0.26 | H16: 0
A17: ABBOUD | B17: Dimitri | C17: dimitri.abboud@edu.escp.eu | D17: e223019 | E17: =IF(AND(G17>=5, H17>=50), "Passed", "Failed") -> Failed | F17: =IF(E17="Passed",ROW(), "") | G17: 0 | H17: 0
A18: ABBOZZO | B18: Cecilia | C18: cecilia.abbozzo@edu.escp.eu | D18: e244924 | E18: =IF(AND(G18>=5, H18>=50), "Passed", "Failed") -> Passed | F18: =IF(E18="Passed",ROW(), "") -> 18 | G18: 7.05 | H18: 96.07 | I18: Complete | J18: Needs Grading | K18: Complete | L18: Complete | M18: Complete | N18: Needs Grading | O18: Complete | P18: Complete
A19: ABCHEE | B19: Antoine | C19: antoine.abchee@edu.escp.eu | D19: e242575 | E19: =IF(AND(G19>=5, H19>=50), "Passed", "Failed") -> Failed | F19: =IF(E19="Passed",ROW(), "") | G19: 0 | H19: 0
A20: ABDALLAH | B20: Jade | C20: jade.abdallah@edu.escp.eu | D20: e245792 | E20: =IF(AND(G20>=5, H20>=50), "Passed", "Failed") -> Failed | F20: =IF(E20="Passed",ROW(), "") | G20: 0 | H20: 0
A21: ABDALLAH | B21: Naya | C21: naya.abdallah2@edu.escp.eu | D21: e245559 | E21: =IF(AND(G21>=5, H21>=50), "Passed", "Failed") -> Failed | F21: =IF(E21="Passed",ROW(), "") | G21: 0 | H21: 0
A22: ABDELALI | B22: Omar | C22: omar.abdelali@edu.escp.eu | D22: e241008 | E22: =IF(AND(G22>=5, H22>=50), "Passed", "Failed") -> Failed | F22: =IF(E22="Passed",ROW(), "") | G22: 0 | H22: 0
A23: ABDELAZIM | B23: Yassmina | C23: yassmina.abdelazim@edu.escp.eu | D23: e244011 | E23: =IF(AND(G23>=5, H23>=50), "Passed", "Failed") -> Failed | F23: =IF(E23="Passed",ROW(), "") | G23: 0.35 | H23: 0
A24: ABDELHADI | B24: Hamza | C24: hamza.abdelhadi@edu.escp.eu | D24: e223471 | E24: =IF(AND(G24>=5, H24>=50), "Passed", "Failed") -> Failed | F24: =IF(E24="Passed",ROW(), "") | G24: 0 | H24: 0
A25: ABDELKEFI | B25: Lyna | C25: lyna.abdelkefi@edu.escp.eu | D25: e224432 | E25: =IF(AND(G25>=5, H25>=50), "Passed", "Failed") -> Failed | F25: =IF(E25="Passed",ROW(), "") | G25: 0 | H25: 0
A26: ABDOUS | B26: Illan | C26: illan.abdous@edu.escp.eu | D26: e244170 | E26: =IF(AND(G26>=5, H26>=50), "Passed", "Failed") -> Failed | F26: =IF(E26="Passed",ROW(), "") | G26: 0 | H26: 0
A27: ABDUL AZEEZ | B27: Sunoon | C27: sunoon.abdul_azeez@edu.escp.eu | D27: e227662 | E27: =IF(AND(G27>=5, H27>=50), "Passed", "Failed") -> Failed | F27: =IF(E27="Passed",ROW(), "") | G27: 0 | H27: 0
A28: ABDULLAEVA | B28: Sharifa | C28: sharifa.abdullaeva@edu.escp.eu | D28: e241434 | E28: =IF(AND(G28>=5, H28>=50), "Passed", "Failed") -> Failed | F28: =IF(E28="Passed",ROW(), "") | G28: 0.01 | H28: 0
A29: ABECASSIS | B29: Anouk | C29: anouk.abecassis@edu.escp.eu | D29: e221861 | E29: =IF(AND(G29>=5, H29>=50), "Passed", "Failed") -> Failed | F29: =IF(E29="Passed",ROW(), "") | G29: 0.33 | H29: 16.33 | I29: Complete | J29: Needs Grading
A30: ABECASSIS | B30: Hillel | C30: hillel.abecassis@edu.escp.eu | D30: e213196 | E30: =IF(AND(G30>=5, H30>=50), "Passed", "Failed") -> Failed | F30: =IF(E30="Passed",ROW(), "") | G30: 0 | H30: 0
A31: ABED | B31: Lotfi | C31: lotfi.abed@edu.escp.eu | D31: e200093 | E31: =IF(AND(G31>=5, H31>=50), "Passed", "Failed") -> Failed | F31: =IF(E31="Passed",ROW(), "") | G31: 0 | H31: 0
A32: ABELLAN MARTINEZ | B32: Diego | C32: diego.abellan_martinez@edu.escp.eu | D32: e209002 | E32: =IF(AND(G32>=5, H32>=50), "Passed", "Failed") -> Failed | F32: =IF(E32="Passed",ROW(), "") | G32: 0 | H32: 0
A33: ABELLY | B33: Lina | C33: lina.abelly@edu.escp.eu | D33: e241009 | E33: =IF(AND(G33>=5, H33>=50), "Passed", "Failed") -> Failed | F33: =IF(E33="Passed",ROW(), "") | G33: 0 | H33: 0
A34: ABENÇOR | B34: Mathilde | C34: mathilde.abencor@edu.escp.eu | D34: e237870 | E34: =IF(AND(G34>=5, H34>=50), "Passed", "Failed") -> Failed | F34: =IF(E34="Passed",ROW(), "") | G34: 0 | H34: 0
A35: ABHEESHTA | B35: Pradeep | C35: pradeep.abheeshta@edu.escp.eu | D35: e244037 | E35: =IF(AND(G35>=5, H35>=50), "Passed", "Failed") -> Failed | F35: =IF(E35="Passed",ROW(), "") | G35: 0 | H35: 0
A36: ABI HAILA | B36: Raphaëlle | C36: raphaelle.abi_haila@edu.escp.eu | D36: e245793 | E36: =IF(AND(G36>=5, H36>=50), "Passed", "Failed") -> Failed | F36: =IF(E36="Passed",ROW(), "") | G36: 0 | H36: 0
A37: ABO CHAKRA | B37: Reina | C37: reina.abo_chakra@edu.escp.eu | D37: e224770 | E37: =IF(AND(G37>=5, H37>=50), "Passed", "Failed") -> Failed | F37: =IF(E37="Passed",ROW(), "") | G37: 0 | H37: 0
A38: ABO MADALALA | B38: Hisham | C38: hisham.abo_madalala@edu.escp.eu | D38: e212219 | E38: =IF(AND(G38>=5, H38>=50), "Passed", "Failed") -> Failed | F38: =IF(E38="Passed",ROW(), "") | G38: 0.04 | H38: 0
A39: ABOU ELIAS | B39: Karim | C39: karim.abou_elias@edu.escp.eu | D39: e228032 | E39: =IF(AND(G39>=5, H39>=50), "Passed", "Failed") -> Failed | F39: =IF(E39="Passed",ROW(), "") | G39: 0.34 | H39: 0 | J39: Needs Grading
A40: ABOU KHAZAA | B40: Elie | C40: elie.abou_khazaa@edu.escp.eu | D40: e244172 | E40: =IF(AND(G40>=5, H40>=50), "Passed", "Failed") -> Failed | F40: =IF(E40="Passed",ROW(), "") | G40: 0 | H40: 0
...

Sheet Removed students
A1: Last Name | B1: First Name | C1: Email | D1: Student ID
A2: ABRAMOVA | B2: Iuliia | C2: iuliia.abramova@edu.escp.eu | D2: e245186
A3: BERTINI COLLA | B3: Leonardo | C3: leonardo.bertini_colla@edu.escp.eu | D3: e236282
A4: BÖLLHOFF | B4: Johannes | C4: johannes.boellhoff@edu.escp.eu | D4: e227572
A5: COLAKIDI | B5: Aristi | C5: aristi.colakidi@edu.escp.eu | D5: e222075
A6: GALAGALI | B6: Deepthi | C6: deepthi.galagali@edu.escp.eu | D6: e238589
A7: GENG | B7: Hongjin | C7: hongjin.geng@edu.escp.eu | D7: e245008
A8: GUYARD | B8: Nicolas | C8: nicolas.guyard@edu.escp.eu | D8: e221140
A9: LOSTIE DE KERHOR | B9: Athénaïs | C9: athenais.lostie_de_kerhor@edu.escp.eu | D9: e230128
A10: MEI | B10: Xiaxing | C10: xiaxing.mei@edu.escp.eu | D10: e242638
A11: RIBEIRO | B11: Carlos | C11: carlos.ribeiro@edu.escp.eu | D11: e244666
A12: SKHASHOK | B12: Iosif | C12: iosif.skhashok@edu.escp.eu | D12: e236189
A13: VAN LEEUWEN | B13: Floor | C13: floor.van_leeuwen@edu.escp.eu | D13: e230046

Sheet Graphs + Statistics

Sheet Passed Students
A1: Last Name | B1: First Name | C1: Email | D1: Student ID | E1: Status
A2: {=IFERROR(INDEX('Course Data'!A:A,SMALL('Course Data'!$F:$F,ROW()-1)),"")} -> ABBOZZO | B2: {=IFERROR(INDEX('Course Data'!B:B,SMALL('Course Data'!$F:$F,ROW()-1)),"")} -> Cecilia | C2: {=IFERROR(INDEX('Course Data'!C:C,SMALL('Course Data'!F:F,ROW()-1)),"")} -> cecilia.abbozzo@edu.escp.eu | D2: {=IFERROR(INDEX('Course Data'!D:D,SMALL('Course Data'!F:F,ROW()-1)),"")} -> e244924 | E2: {=IFERROR(INDEX('Course Data'!E:E,SMALL('Course Data'!F:F,ROW()-1)),"")} -> Passed
A3: {=IFERROR(INDEX('Course Data'!A:A,SMALL('Course Data'!$F:$F,ROW()-1)),"")} -> ABOU SAADA NOUJEIM | B3: {=IFERROR(INDEX('Course Data'!B:B,SMALL('Course Data'!$F:$F,ROW()-1)),"")} -> Daniel | C3: {=IFERROR(INDEX('Course Data'!C:C,SMALL('Course Data'!F:F,ROW()-1)),"")} -> daniel.abou_saada_noujeim@edu.escp.eu | D3: {=IFERROR(INDEX('Course Data'!D:D,SMALL('Course Data'!F:F,ROW()-1)),"")} -> e245358 | E3: {=IFERROR(INDEX('Course Data'!E:E,SMALL('Course Data'!F:F,ROW()-1)),"")} -> Passed
A4: {=IFERROR(INDEX('Course Data'!A:A,SMALL('Course Data'!$F:$F,ROW()-1)),"")} -> AUCOUTURIER | B4: {=IFERROR(INDEX('Course Data'!B:B,SMALL('Course Data'!$F:$F,ROW()-1)),"")} -> Maxence | C4: {=IFERROR(INDEX('Course Data'!C:C,SMALL('Course Data'!F:F,ROW()-1)),"")} -> maxence.aucouturier@edu.escp.eu | D4: {=IFERROR(INDEX('Course Data'!D:D,SMALL('Course Data'!F:F,ROW()-1)),"")} -> e221864 | E4: {=IFERROR(INDEX('Course Data'!E:E,SMALL('Course Data'!F:F,ROW()-1)),"")} -> Passed
A5: {=IFERROR(INDEX('Course Data'!A:A,SMALL('Course Data'!$F:$F,ROW()-1)),"")} -> AUTRET | B5: {=IFERROR(INDEX('Course Data'!B:B,SMALL('Course Data'!$F:$F,ROW()-1)),"")} -> Arthur | C5: {=IFERROR(INDEX('Course Data'!C:C,SMALL('Course Data'!F:F,ROW()-1)),"")} -> arthur.autret@edu.escp.eu | D5: {=IFERROR(INDEX('Course Data'!D:D,SMALL('Course Data'!F:F,ROW()-1)),"")} -> e234397 | E5: {=IFERROR(INDEX('Course Data'!E:E,SMALL('Course Data'!F:F,ROW()-1)),"")} -> Passed
A6: {=IFERROR(INDEX('Course Data'!A:A,SMALL('Course Data'!$F:$F,ROW()-1)),"")} -> Bali | B6: {=IFERROR(INDEX('Course Data'!B:B,SMALL('Course Data'!$F:$F,ROW()-1)),"")} -> Sejir | C6: {=IFERROR(INDEX('Course Data'!C:C,SMALL('Course Data'!F:F,ROW()-1)),"")} | D6: {=IFERROR(INDEX('Course Data'!D:D,SMALL('Course Data'!F:F,ROW()-1)),"")} -> sbali | E6: {=IFERROR(INDEX('Course Data'!E:E,SMALL('Course Data'!F:F,ROW()-1)),"")} -> Passed
A7: {=IFERROR(INDEX('Course Data'!A:A,SMALL('Course Data'!$F:$F,ROW()-1)),"")} -> BAROUKY | B7: {=IFERROR(INDEX('Course Data'!B:B,SMALL('Course Data'!$F:$F,ROW()-1)),"")} -> Clara | C7: {=IFERROR(INDEX('Course Data'!C:C,SMALL('Course Data'!F:F,ROW()-1)),"")} -> clara.barouky@edu.escp.eu | D7: {=IFERROR(INDEX('Course Data'!D:D,SMALL('Course Data'!F:F,ROW()-1)),"")} -> e220066 | E7: {=IFERROR(INDEX('Course Data'!E:E,SMALL('Course Data'!F:F,ROW()-1)),"")} -> Passed
A8: {=IFERROR(INDEX('Course Data'!A:A,SMALL('Course Data'!$F:$F,ROW()-1)),"")} -> BARZAGHI | B8: {=IFERROR(INDEX('Course Data'!B:B,SMALL('Course Data'!$F:$F,ROW()-1)),"")} -> Ludovica Vittoria | C8: {=IFERROR(INDEX('Course Data'!C:C,SMALL('Course Data'!F:F,ROW()-1)),"")} -> ludovica_vittoria.barzaghi@edu.escp.eu | D8: {=IFERROR(INDEX('Course Data'!D:D,SMALL('Course Data'!F:F,ROW()-1)),"")} -> e234125 | E8: {=IFERROR(INDEX('Course Data'!E:E,SMALL('Course Data'!F:F,ROW()-1)),"")} -> Passed
A9: {=IFERROR(INDEX('Course Data'!A:A,SMALL('Course Data'!$F:$F,ROW()-1)),"")} -> BASSO | B9: {=IFERROR(INDEX('Course Data'!B:B,SMALL('Course Data'!$F:$F,ROW()-1)),"")} -> Asia | C9: {=IFERROR(INDEX('Course Data'!C:C,SMALL('Course Data'!F:F,ROW()-1)),"")} -> asia.basso@edu.escp.eu | D9: {=IFERROR(INDEX('Course Data'!D:D,SMALL('Course Data'!F:F,ROW()-1)),"")} -> e240738 | E9: {=IFERROR(INDEX('Course Data'!E:E,SMALL('Course Data'!F:F,ROW()-1)),"")} -> Passed
A10: {=IFERROR(INDEX('Course Data'!A:A,SMALL('Course Data'!$F:$F,ROW()-1)),"")} -> BATTINI | B10: {=IFERROR(INDEX('Course Data'!B:B,SMALL('Course Data'!$F:$F,ROW()-1)),"")} -> Chiara | C10: {=IFERROR(INDEX('Course Data'!C:C,SMALL('Course Data'!F:F,ROW()-1)),"")} -> chiara.battini2@edu.escp.eu | D10: {=IFERROR(INDEX('Course Data'!D:D,SMALL('Course Data'!F:F,ROW()-1)),"")} -> e238525 | E10: {=IFERROR(INDEX('Course Data'!E:E,SMALL('Course Data'!F:F,ROW()-1)),"")} -> Passed
A11: {=IFERROR(INDEX('Course Data'!A:A,SMALL('Course Data'!$F:$F,ROW()-1)),"")} -> BELOUIN | B11: {=IFERROR(INDEX('Course Data'!B:B,SMALL('Course Data'!$F:$F,ROW()-1)),"")} -> Jules | C11: {=IFERROR(INDEX('Course Data'!C:C,SMALL('Course Data'!F:F,ROW()-1)),"")} -> jules.belouin@edu.escp.eu | D11: {=IFERROR(INDEX('Course Data'!D:D,SMALL('Course Data'!F:F,ROW()-1)),"")} -> e220069 | E11: {=IFERROR(INDEX('Course Data'!E:E,SMALL('Course Data'!F:F,ROW()-1)),"")} -> Passed
A12: {=IFERROR(INDEX('Course Data'!A:A,SMALL('Course Data'!$F:$F,ROW()-1)),"")} -> BELTCHIKOV | B12: {=IFERROR(INDEX('Course Data'!B:B,SMALL('Course Data'!$F:$F,ROW()-1)),"")} -> Vladimir | C12: {=IFERROR(INDEX('Course Data'!C:C,SMALL('Course Data'!F:F,ROW()-1)),"")} -> vladimir.beltchikov@edu.escp.eu | D12: {=IFERROR(INDEX('Course Data'!D:D,SMALL('Course Data'!F:F,ROW()-1)),"")} -> e220856 | E12: {=IFERROR(INDEX('Course Data'!E:E,SMALL('Course Data'!F:F,ROW()-1)),"")} -> Passed
A13: {=IFERROR(INDEX('Course Data'!A:A,SMALL('Course Data'!$F:$F,ROW()-1)),"")} -> BENSIALI | B13: {=IFERROR(INDEX('Course Data'!B:B,SMALL('Course Data'!$F:$F,ROW()-1)),"")} -> Rayane | C13: {=IFERROR(INDEX('Course Data'!C:C,SMALL('Course Data'!F:F,ROW()-1)),"")} -> rayane.bensiali@edu.escp.eu | D13: {=IFERROR(INDEX('Course Data'!D:D,SMALL('Course Data'!F:F,ROW()-1)),"")} -> e241029 | E13: {=IFERROR(INDEX('Course Data'!E:E,SMALL('Course Data'!F:F,ROW()-1)),"")} -> Passed
... A79: {=IFERROR(INDEX('Course Data'!A:A,SMALL('Course Data'!$F:$F,ROW()-1)),"")} -> ZHUO | B79: {=IFERROR(INDEX('Course Data'!B:B,SMALL('Course Data'!$F:$F,ROW()-1)),"")} -> Yiwen | C79: {=IFERROR(INDEX('Course Data'!C:C,SMALL('Course Data'!F:F,ROW()-1)),"")} -> yiwen.zhuo@edu.escp.eu | D79: {=IFERROR(INDEX('Course Data'!D:D,SMALL('Course Data'!F:F,ROW()-1)),"")} -> e224295 | E79: {=IFERROR(INDEX('Course Data'!E:E,SMALL('Course Data'!F:F,ROW()-1)),"")} -> Passed

Sheet Summary
A1: Hours Summary | B1: Grade + Hours
A2: =IF('Course Data'!G2=0,"0 hours",IF('Course Data'!G2<5,"Less than 5 hours",IF('Course Data'!G2>=5,"More than 5 hours"))) -> Less than 5 hours | B2: =IF(AND('Course Data'!G2>=5,'Course Data'!H2<50),"More than 5 hours but ovreall grade lower than 50%", IF(AND('Course Data'!G2<5,'Course Data'!H2>=50),"Less than 5 hours but overall grade higher than 50%", IF('Course Data'!E2="Passed","Passed", "Incomplete or failed"))) -> Incomplete or failed
A3: =IF('Course Data'!G3=0,"0 hours",IF('Course Data'!G3<5,"Less than 5 hours",IF('Course Data'!G3>=5,"More than 5 hours"))) -> Less than 5 hours | B3: =IF(AND('Course Data'!G3>=5,'Course Data'!H3<50),"More than 5 hours but ovreall grade lower than 50%", IF(AND('Course Data'!G3<5,'Course Data'!H3>=50),"Less than 5 hours but overall grade higher than 50%", IF('Course Data'!E3="Passed","Passed", "Incomplete or failed"))) -> Incomplete or failed
A4: =IF('Course Data'!G4=0,"0 hours",IF('Course Data'!G4<5,"Less than 5 hours",IF('Course Data'!G4>=5,"More than 5 hours"))) -> 0 hours | B4: =IF(AND('Course Data'!G4>=5,'Course Data'!H4<50),"More than 5 hours but ovreall grade lower than 50%", IF(AND('Course Data'!G4<5,'Course Data'!H4>=50),"Less than 5 hours but overall grade higher than 50%", IF('Course Data'!E4="Passed","Passed", "Incomplete or failed"))) -> Incomplete or failed
A5: =IF('Course Data'!G5=0,"0 hours",IF('Course Data'!G5<5,"Less than 5 hours",IF('Course Data'!G5>=5,"More than 5 hours"))) -> Less than 5 hours | B5: =IF(AND('Course Data'!G5>=5,'Course Data'!H5<50),"More than 5 hours but ovreall grade lower than 50%", IF(AND('Course Data'!G5<5,'Course Data'!H5>=50),"Less than 5 hours but overall grade higher than 50%", IF('Course Data'!E5="Passed","Passed", "Incomplete or failed"))) -> Incomplete or failed
A6: =IF('Course Data'!G6=0,"0 hours",IF('Course Data'!G6<5,"Less than 5 hours",IF('Course Data'!G6>=5,"More than 5 hours"))) -> Less than 5 hours | B6: =IF(AND('Course Data'!G6>=5,'Course Data'!H6<50),"More than 5 hours but ovreall grade lower than 50%", IF(AND('Course Data'!G6<5,'Course Data'!H6>=50),"Less than 5 hours but overall grade higher than 50%", IF('Course Data'!E6="Passed","Passed", "Incomplete or failed"))) -> Incomplete or failed
A7: =IF('Course Data'!G7=0,"0 hours",IF('Course Data'!G7<5,"Less than 5 hours",IF('Course Data'!G7>=5,"More than 5 hours"))) -> 0 hours | B7: =IF(AND('Course Data'!G7>=5,'Course Data'!H7<50),"More than 5 hours but ovreall grade lower than 50%", IF(AND('Course Data'!G7<5,'Course Data'!H7>=50),"Less than 5 hours but overall grade higher than 50%", IF('Course Data'!E7="Passed","Passed", "Incomplete or failed"))) -> Incomplete or failed
A8: =IF('Course Data'!G8=0,"0 hours",IF('Course Data'!G8<5,"Less than 5 hours",IF('Course Data'!G8>=5,"More than 5 hours"))) -> 0 hours | B8: =IF(AND('Course Data'!G8>=5,'Course Data'!H8<50),"More than 5 hours but ovreall grade lower than 50%", IF(AND('Course Data'!G8<5,'Course Data'!H8>=50),"Less than 5 hours but overall grade higher than 50%", IF('Course Data'!E8="Passed","Passed", "Incomplete or failed"))) -> Incomplete or failed
A9: =IF('Course Data'!G9=0,"0 hours",IF('Course Data'!G9<5,"Less than 5 hours",IF('Course Data'!G9>=5,"More than 5 hours"))) -> 0 hours | B9: =IF(AND('Course Data'!G9>=5,'Course Data'!H9<50),"More than 5 hours but ovreall grade lower than 50%", IF(AND('Course Data'!G9<5,'Course Data'!H9>=50),"Less than 5 hours but overall grade higher than 50%", IF('Course Data'!E9="Passed","Passed", "Incomplete or failed"))) -> Incomplete or failed
A10: =IF('Course Data'!G10=0,"0 hours",IF('Course Data'!G10<5,"Less than 5 hours",IF('Course Data'!G10>=5,"More than 5 hours"))) -> 0 hours | B10: =IF(AND('Course Data'!G10>=5,'Course Data'!H10<50),"More than 5 hours but ovreall grade lower than 50%", IF(AND('Course Data'!G10<5,'Course Data'!H10>=50),"Less than 5 hours but overall grade higher than 50%", IF('Course Data'!E10="Passed","Passed", "Incomplete or failed"))) -> Incomplete or failed
A11: =IF('Course Data'!G11=0,"0 hours",IF('Course Data'!G11<5,"Less than 5 hours",IF('Course Data'!G11>=5,"More than 5 hours"))) -> 0 hours | B11: =IF(AND('Course Data'!G11>=5,'Course Data'!H11<50),"More than 5 hours but ovreall grade lower than 50%", IF(AND('Course Data'!G11<5,'Course Data'!H11>=50),"Less than 5 hours but overall grade higher than 50%", IF('Course Data'!E11="Passed","Passed", "Incomplete or failed"))) -> Incomplete or failed
A12: =IF('Course Data'!G12=0,"0 hours",IF('Course Data'!G12<5,"Less than 5 hours",IF('Course Data'!G12>=5,"More than 5 hours"))) -> 0 hours | B12: =IF(AND('Course Data'!G12>=5,'Course Data'!H12<50),"More than 5 hours but ovreall grade lower than 50%", IF(AND('Course Data'!G12<5,'Course Data'!H12>=50),"Less than 5 hours but overall grade higher than 50%", IF('Course Data'!E12="Passed","Passed", "Incomplete or failed"))) -> Incomplete or failed
A13: =IF('Course Data'!G13=0,"0 hours",IF('Course Data'!G13<5,"Less than 5 hours",IF('Course Data'!G13>=5,"More than 5 hours"))) -> 0 hours | B13: =IF(AND('Course Data'!G13>=5,'Course Data'!H13<50),"More than 5 hours but ovreall grade lower than 50%", IF(AND('Course Data'!G13<5,'Course Data'!H13>=50),"Less than 5 hours but overall grade higher than 50%", IF('Course Data'!E13="Passed","Passed", "Incomplete or failed"))) -> Incomplete or failed
... A8891: =IF('Course Data'!G8891=0,"0 hours",IF('Course Data'!G8891<5,"Less than 5 hours",IF('Course Data'!G8891>=5,"More than 5 hours"))) -> 0 hours | B8891: =IF(AND('Course Data'!G8891>=5,'Course Data'!H8891<50),"More than 5 hours but ovreall grade lower than 50%", IF(AND('Course Data'!G8891<5,'Course Data'!H8891>=50),"Less than 5 hours but overall grade higher than 50%", IF('Course Data'!E8891="Passed","Passed", "Incomplete or failed"))) -> Incomplete or failed
